<?xml version="1.0" ?>
<!-- =================================================================================== -->
<!-- |    This document was autogenerated by xacro from r2d2_model.urdf.xacro          | -->
<!-- |    EDITING THIS FILE BY HAND IS NOT RECOMMENDED                                 | -->
<!-- =================================================================================== -->
<robot name="r2d2_xacro_mod">
  <!-- _____________________ MATERIALS AND COLORS ______________________ -->
  <material name="blue">
    <color rgba="0 0 0.8 1"/>
  </material>
  <material name="black">
    <color rgba="0 0 0 1"/>
  </material>
  <material name="white">
    <color rgba="1 1 1 1"/>
  </material>
  <material name="semi_white">
    <color rgba="0.8 0.8 0.8 1"/>
  </material>
  <material name="red">
    <color rgba="0.9 0.0 0.0 1.0"/>
  </material>
  <material name="gray">
    <color rgba="0.5 0.5 0.5 1.0"/>
  </material>
  <!-- ____________________ BASE LINK IMPLEMENTATION ____________________-->
  <link name="base_link">
    <visual>
      <geometry>
        <cylinder length="0.6" radius="0.2"/>
      </geometry>
      <material name="white"/>
    </visual>
    <collision>
      <geometry>
        <cylinder length="0.6" radius="0.2"/>
      </geometry>
    </collision>
    <inertial>
      <mass value="10"/>
      <inertia ixx="1.0" ixy="0.0" ixz="0.0" iyy="1.0" iyz="0.0" izz="1.0"/>
    </inertial>
  </link>
  <link name="right_shoulder">
    <visual>
      <geometry>
        <sphere radius="0.12"/>
      </geometry>
      <material name="white"/>
    </visual>
    <collision>
      <geometry>
        <sphere radius="0.12"/>
      </geometry>
    </collision>
    <inertial>
      <mass value="5"/>
      <inertia ixx="1.0" ixy="0.0" ixz="0.0" iyy="1.0" iyz="0.0" izz="1.0"/>
    </inertial>
  </link>
  <joint name="base_to_right_shoulder" type="revolute">
    <axis xyz="0 1 0"/>
    <limit effort="1000.0" lower="-0.3" upper="0.3" velocity="0.5"/>
    <parent link="base_link"/>
    <child link="right_shoulder"/>
    <origin xyz="0 -0.2 0.20"/>
  </joint>
  <link name="right_protection">
    <visual>
      <geometry>
        <sphere radius="0.09839999999999999"/>
      </geometry>
      <origin xyz="0 0 0.036"/>
      <material name="white"/>
    </visual>
    <collision>
      <geometry>
        <sphere radius="0.09839999999999999"/>
      </geometry>
    </collision>
  </link>
  <joint name="protection_to_right_shoulder" type="fixed">
    <parent link="right_shoulder"/>
    <child link="right_protection"/>
  </joint>
  <link name="right_leg">
    <visual>
      <geometry>
        <box size="0.6 0.1 0.2"/>
      </geometry>
      <origin rpy="0 1.5707963267948966 0" xyz="0 0 -0.3"/>
      <material name="white"/>
    </visual>
    <collision>
      <geometry>
        <box size="0.6 0.1 0.2"/>
      </geometry>
      <origin rpy="0 1.5707963267948966 0" xyz="0 0 -0.3"/>
    </collision>
    <inertial>
      <mass value="10"/>
      <inertia ixx="1.0" ixy="0.0" ixz="0.0" iyy="1.0" iyz="0.0" izz="1.0"/>
    </inertial>
  </link>
  <joint name="shoulder_to_right_leg" type="fixed">
    <parent link="right_shoulder"/>
    <child link="right_leg"/>
    <origin xyz="0 -0.02 0"/>
  </joint>
  <link name="right_piston">
    <visual>
      <geometry>
        <cylinder length="0.5" radius="0.05"/>
      </geometry>
      <origin xyz="0 -0.05 -0.3"/>
      <material name="blue"/>
    </visual>
    <collision>
      <geometry>
        <cylinder length="0.5" radius="0.05"/>
      </geometry>
      <origin xyz="0 -0.05 -0.3"/>
    </collision>
  </link>
  <joint name="piston_to_right_leg" type="fixed">
    <parent link="right_leg"/>
    <child link="right_piston"/>
    <origin xyz="0 0 0.05"/>
  </joint>
  <link name="right_base">
    <visual>
      <geometry>
        <box size="0.4 0.1 0.1"/>
      </geometry>
      <material name="white"/>
    </visual>
    <collision>
      <geometry>
        <box size="0.4 0.1 0.1"/>
      </geometry>
    </collision>
    <inertial>
      <mass value="10"/>
      <inertia ixx="1.0" ixy="0.0" ixz="0.0" iyy="1.0" iyz="0.0" izz="1.0"/>
    </inertial>
  </link>
  <joint name="right_base_joint" type="fixed">
    <parent link="right_leg"/>
    <child link="right_base"/>
    <origin xyz="0 0 -0.6"/>
  </joint>
  <link name="right_front_wheel">
    <visual>
      <origin rpy="1.5707963267948966 0 0" xyz="0 0 0"/>
      <geometry>
        <cylinder length="0.1" radius="0.035"/>
      </geometry>
      <material name="black"/>
    </visual>
    <collision>
      <origin rpy="1.5707963267948966 0 0" xyz="0 0 0"/>
      <geometry>
        <cylinder length="0.1" radius="0.035"/>
      </geometry>
    </collision>
    <inertial>
      <mass value="1"/>
      <inertia ixx="1.0" ixy="0.0" ixz="0.0" iyy="1.0" iyz="0.0" izz="1.0"/>
    </inertial>
  </link>
  <joint name="right_front_wheel_joint" type="continuous">
    <axis rpy="0 0 0" xyz="0 1 0"/>
    <parent link="right_base"/>
    <child link="right_front_wheel"/>
    <origin rpy="0 0 0" xyz="0.13333333333333333 0 -0.085"/>
  </joint>
  <link name="right_back_wheel">
    <visual>
      <origin rpy="1.5707963267948966 0 0" xyz="0 0 0"/>
      <geometry>
        <cylinder length="0.1" radius="0.035"/>
      </geometry>
      <material name="black"/>
    </visual>
    <collision>
      <origin rpy="1.5707963267948966 0 0" xyz="0 0 0"/>
      <geometry>
        <cylinder length="0.1" radius="0.035"/>
      </geometry>
    </collision>
    <inertial>
      <mass value="1"/>
      <inertia ixx="1.0" ixy="0.0" ixz="0.0" iyy="1.0" iyz="0.0" izz="1.0"/>
    </inertial>
  </link>
  <joint name="right_back_wheel_joint" type="continuous">
    <axis rpy="0 0 0" xyz="0 1 0"/>
    <parent link="right_base"/>
    <child link="right_back_wheel"/>
    <origin rpy="0 0 0" xyz="-0.13333333333333333 0 -0.085"/>
  </joint>
  <link name="left_shoulder">
    <visual>
      <geometry>
        <sphere radius="0.12"/>
      </geometry>
      <material name="white"/>
    </visual>
    <collision>
      <geometry>
        <sphere radius="0.12"/>
      </geometry>
    </collision>
    <inertial>
      <mass value="5"/>
      <inertia ixx="1.0" ixy="0.0" ixz="0.0" iyy="1.0" iyz="0.0" izz="1.0"/>
    </inertial>
  </link>
  <joint name="base_to_left_shoulder" type="revolute">
    <axis xyz="0 1 0"/>
    <limit effort="1000.0" lower="-0.3" upper="0.3" velocity="0.5"/>
    <parent link="base_link"/>
    <child link="left_shoulder"/>
    <origin xyz="0 0.2 0.20"/>
  </joint>
  <link name="left_protection">
    <visual>
      <geometry>
        <sphere radius="0.09839999999999999"/>
      </geometry>
      <origin xyz="0 0 0.036"/>
      <material name="white"/>
    </visual>
    <collision>
      <geometry>
        <sphere radius="0.09839999999999999"/>
      </geometry>
    </collision>
  </link>
  <joint name="protection_to_left_shoulder" type="fixed">
    <parent link="left_shoulder"/>
    <child link="left_protection"/>
  </joint>
  <link name="left_leg">
    <visual>
      <geometry>
        <box size="0.6 0.1 0.2"/>
      </geometry>
      <origin rpy="0 1.5707963267948966 0" xyz="0 0 -0.3"/>
      <material name="white"/>
    </visual>
    <collision>
      <geometry>
        <box size="0.6 0.1 0.2"/>
      </geometry>
      <origin rpy="0 1.5707963267948966 0" xyz="0 0 -0.3"/>
    </collision>
    <inertial>
      <mass value="10"/>
      <inertia ixx="1.0" ixy="0.0" ixz="0.0" iyy="1.0" iyz="0.0" izz="1.0"/>
    </inertial>
  </link>
  <joint name="shoulder_to_left_leg" type="fixed">
    <parent link="left_shoulder"/>
    <child link="left_leg"/>
    <origin xyz="0 0.02 0"/>
  </joint>
  <link name="left_piston">
    <visual>
      <geometry>
        <cylinder length="0.5" radius="0.05"/>
      </geometry>
      <origin xyz="0 0.05 -0.3"/>
      <material name="blue"/>
    </visual>
    <collision>
      <geometry>
        <cylinder length="0.5" radius="0.05"/>
      </geometry>
      <origin xyz="0 0.05 -0.3"/>
    </collision>
  </link>
  <joint name="piston_to_left_leg" type="fixed">
    <parent link="left_leg"/>
    <child link="left_piston"/>
    <origin xyz="0 0 0.05"/>
  </joint>
  <link name="left_base">
    <visual>
      <geometry>
        <box size="0.4 0.1 0.1"/>
      </geometry>
      <material name="white"/>
    </visual>
    <collision>
      <geometry>
        <box size="0.4 0.1 0.1"/>
      </geometry>
    </collision>
    <inertial>
      <mass value="10"/>
      <inertia ixx="1.0" ixy="0.0" ixz="0.0" iyy="1.0" iyz="0.0" izz="1.0"/>
    </inertial>
  </link>
  <joint name="left_base_joint" type="fixed">
    <parent link="left_leg"/>
    <child link="left_base"/>
    <origin xyz="0 0 -0.6"/>
  </joint>
  <link name="left_front_wheel">
    <visual>
      <origin rpy="1.5707963267948966 0 0" xyz="0 0 0"/>
      <geometry>
        <cylinder length="0.1" radius="0.035"/>
      </geometry>
      <material name="black"/>
    </visual>
    <collision>
      <origin rpy="1.5707963267948966 0 0" xyz="0 0 0"/>
      <geometry>
        <cylinder length="0.1" radius="0.035"/>
      </geometry>
    </collision>
    <inertial>
      <mass value="1"/>
      <inertia ixx="1.0" ixy="0.0" ixz="0.0" iyy="1.0" iyz="0.0" izz="1.0"/>
    </inertial>
  </link>
  <joint name="left_front_wheel_joint" type="continuous">
    <axis rpy="0 0 0" xyz="0 1 0"/>
    <parent link="left_base"/>
    <child link="left_front_wheel"/>
    <origin rpy="0 0 0" xyz="0.13333333333333333 0 -0.085"/>
  </joint>
  <link name="left_back_wheel">
    <visual>
      <origin rpy="1.5707963267948966 0 0" xyz="0 0 0"/>
      <geometry>
        <cylinder length="0.1" radius="0.035"/>
      </geometry>
      <material name="black"/>
    </visual>
    <collision>
      <origin rpy="1.5707963267948966 0 0" xyz="0 0 0"/>
      <geometry>
        <cylinder length="0.1" radius="0.035"/>
      </geometry>
    </collision>
    <inertial>
      <mass value="1"/>
      <inertia ixx="1.0" ixy="0.0" ixz="0.0" iyy="1.0" iyz="0.0" izz="1.0"/>
    </inertial>
  </link>
  <joint name="left_back_wheel_joint" type="continuous">
    <axis rpy="0 0 0" xyz="0 1 0"/>
    <parent link="left_base"/>
    <child link="left_back_wheel"/>
    <origin rpy="0 0 0" xyz="-0.13333333333333333 0 -0.085"/>
  </joint>
  <joint name="left_gripper_joint" type="revolute">
    <axis xyz="0 0 1"/>
    <limit effort="1000.0" lower="0.0" upper="0.548" velocity="0.5"/>
    <origin rpy="0 0 0" xyz="0.2 0.01 0"/>
    <parent link="gripper_pole"/>
    <child link="left_gripper"/>
  </joint>
  <link name="left_gripper">
    <visual>
      <origin rpy="0.0 0 0" xyz="0 0 0"/>
      <geometry>
        <mesh filename="package://m03_using_urdf/meshes/l_finger.dae"/>
      </geometry>
    </visual>
    <collision>
      <geometry>
        <mesh filename="package://m03_using_urdf/meshes/l_finger.dae"/>
      </geometry>
      <origin rpy="0.0 0 0" xyz="0 0 0"/>
    </collision>
    <inertial>
      <mass value="0.05"/>
      <inertia ixx="1.0" ixy="0.0" ixz="0.0" iyy="1.0" iyz="0.0" izz="1.0"/>
    </inertial>
  </link>
  <joint name="left_tip_joint" type="fixed">
    <parent link="left_gripper"/>
    <child link="left_tip"/>
  </joint>
  <link name="left_tip">
    <visual>
      <origin rpy="0.0 0 0" xyz="0.09137 0.00495 0"/>
      <geometry>
        <mesh filename="package://m03_using_urdf/meshes/l_finger_tip.dae"/>
      </geometry>
    </visual>
    <collision>
      <geometry>
        <mesh filename="package://m03_using_urdf/meshes/l_finger_tip.dae"/>
      </geometry>
      <origin rpy="0.0 0 0" xyz="0.09137 0.00495 0"/>
    </collision>
    <inertial>
      <mass value="0.05"/>
      <inertia ixx="1.0" ixy="0.0" ixz="0.0" iyy="1.0" iyz="0.0" izz="1.0"/>
    </inertial>
  </link>
  <joint name="right_gripper_joint" type="revolute">
    <axis xyz="0 0 -1"/>
    <limit effort="1000.0" lower="0.0" upper="0.548" velocity="0.5"/>
    <origin rpy="0 0 0" xyz="0.2 -0.01 0"/>
    <parent link="gripper_pole"/>
    <child link="right_gripper"/>
  </joint>
  <link name="right_gripper">
    <visual>
      <origin rpy="-3.141592653589793 0 0" xyz="0 0 0"/>
      <geometry>
        <mesh filename="package://m03_using_urdf/meshes/l_finger.dae"/>
      </geometry>
    </visual>
    <collision>
      <geometry>
        <mesh filename="package://m03_using_urdf/meshes/l_finger.dae"/>
      </geometry>
      <origin rpy="-3.141592653589793 0 0" xyz="0 0 0"/>
    </collision>
    <inertial>
      <mass value="0.05"/>
      <inertia ixx="1.0" ixy="0.0" ixz="0.0" iyy="1.0" iyz="0.0" izz="1.0"/>
    </inertial>
  </link>
  <joint name="right_tip_joint" type="fixed">
    <parent link="right_gripper"/>
    <child link="right_tip"/>
  </joint>
  <link name="right_tip">
    <visual>
      <origin rpy="-3.141592653589793 0 0" xyz="0.09137 0.00495 0"/>
      <geometry>
        <mesh filename="package://m03_using_urdf/meshes/l_finger_tip.dae"/>
      </geometry>
    </visual>
    <collision>
      <geometry>
        <mesh filename="package://m03_using_urdf/meshes/l_finger_tip.dae"/>
      </geometry>
      <origin rpy="-3.141592653589793 0 0" xyz="0.09137 0.00495 0"/>
    </collision>
    <inertial>
      <mass value="0.05"/>
      <inertia ixx="1.0" ixy="0.0" ixz="0.0" iyy="1.0" iyz="0.0" izz="1.0"/>
    </inertial>
  </link>
  <link name="vent_plat">
    <visual>
      <geometry>
        <box size="0.1 0.1 0.25"/>
      </geometry>
      <material name="blue"/>
    </visual>
  </link>
  <joint name="base_to_vent_plat" type="fixed">
    <parent link="base_link"/>
    <child link="vent_plat"/>
    <origin xyz="0.17 0.0 0.05"/>
  </joint>
  <link name="left_door">
    <visual>
      <geometry>
        <box size="0.1 0.05 0.25"/>
      </geometry>
      <material name="semi_white"/>
    </visual>
  </link>
  <joint name="base_to_left_door" type="fixed">
    <parent link="base_link"/>
    <child link="left_door"/>
    <origin xyz="0.145 0.10500000000000001 0.05"/>
  </joint>
  <link name="right_door">
    <visual>
      <geometry>
        <box size="0.1 0.05 0.25"/>
      </geometry>
      <material name="semi_white"/>
    </visual>
  </link>
  <joint name="base_to_right_door" type="fixed">
    <parent link="base_link"/>
    <child link="right_door"/>
    <origin xyz="0.145 -0.10500000000000001 0.05"/>
  </joint>
  <link name="blue1_door">
    <visual>
      <geometry>
        <box size="0.1 0.25 0.034999999999999996"/>
      </geometry>
      <material name="blue"/>
    </visual>
  </link>
  <joint name="base_to_blue1_door" type="fixed">
    <parent link="base_link"/>
    <child link="blue1_door"/>
    <origin xyz="0.1525 0.0 0.25"/>
  </joint>
  <link name="blue2_door">
    <visual>
      <geometry>
        <box size="0.1 0.25 0.034999999999999996"/>
      </geometry>
      <material name="blue"/>
    </visual>
  </link>
  <joint name="base_to_blue2_door" type="fixed">
    <parent link="base_link"/>
    <child link="blue2_door"/>
    <origin xyz="0.1525 0.0 0.2"/>
  </joint>
  <link name="head">
    <visual>
      <geometry>
        <sphere radius="0.2"/>
      </geometry>
      <material name="white"/>
    </visual>
    <collision>
      <geometry>
        <sphere radius="0.2"/>
      </geometry>
    </collision>
    <inertial>
      <mass value="2"/>
      <inertia ixx="1.0" ixy="0.0" ixz="0.0" iyy="1.0" iyz="0.0" izz="1.0"/>
    </inertial>
  </link>
  <joint name="head_swivel" type="continuous">
    <parent link="base_link"/>
    <child link="head"/>
    <axis xyz="0 0 1"/>
    <origin xyz="0 0 0.3157894736842105"/>
  </joint>
  <link name="neck">
    <visual>
      <geometry>
        <sphere radius="0.2"/>
      </geometry>
      <material name="blue"/>
    </visual>
    <collision>
      <geometry>
        <sphere radius="0.2"/>
      </geometry>
    </collision>
    <inertial>
      <mass value="2"/>
      <inertia ixx="1.0" ixy="0.0" ixz="0.0" iyy="1.0" iyz="0.0" izz="1.0"/>
    </inertial>
  </link>
  <joint name="neck_swivel" type="fixed">
    <parent link="head"/>
    <child link="neck"/>
    <axis xyz="0 0 1"/>
    <origin xyz="0 0 -0.012"/>
  </joint>
  <link name="dec_1">
    <visual>
      <origin rpy="0 0 -0.22999999999999998"/>
      <geometry>
        <box size="0.06 0.035 0.06"/>
      </geometry>
      <material name="blue"/>
    </visual>
    <collision>
      <origin rpy="0 0 -0.22999999999999998"/>
      <geometry>
        <box size="0.06 0.035 0.06"/>
      </geometry>
    </collision>
  </link>
  <joint name="to_dec_1" type="fixed">
    <parent link="head"/>
    <child link="dec_1"/>
    <origin xyz="0.17 -0.05500000000000001 0.045000000000000005"/>
  </joint>
  <link name="dec_2">
    <visual>
      <origin rpy="0 0 -0.6000000000000001"/>
      <geometry>
        <box size="0.06 0.035 0.06"/>
      </geometry>
      <material name="blue"/>
    </visual>
    <collision>
      <origin rpy="0 0 -0.6000000000000001"/>
      <geometry>
        <box size="0.06 0.035 0.06"/>
      </geometry>
    </collision>
  </link>
  <joint name="to_dec_2" type="fixed">
    <parent link="head"/>
    <child link="dec_2"/>
    <origin xyz="0.135 -0.1105 0.045000000000000005"/>
  </joint>
  <link name="base_light">
    <visual>
      <origin rpy="0 0 0.22999999999999998"/>
      <geometry>
        <box size="0.06 0.08 0.06"/>
      </geometry>
      <material name="blue"/>
    </visual>
    <collision>
      <origin rpy="0 0 0.22999999999999998"/>
      <geometry>
        <box size="0.06 0.08 0.06"/>
      </geometry>
    </collision>
  </link>
  <joint name="to_base_light" type="fixed">
    <parent link="head"/>
    <child link="base_light"/>
    <origin xyz="0.18000000000000002 0.020000000000000004 0.045000000000000005"/>
  </joint>
  <link name="eye">
    <visual>
      <origin rpy="0 0 0.0"/>
      <geometry>
        <box size="0.08 0.08 0.08"/>
      </geometry>
      <material name="blue"/>
    </visual>
    <collision>
      <origin rpy="0 0 0.0"/>
      <geometry>
        <box size="0.08 0.08 0.08"/>
      </geometry>
    </collision>
  </link>
  <joint name="to_eye" type="fixed">
    <parent link="head"/>
    <child link="eye"/>
    <origin xyz="0.1414 0.0 0.12140000000000001"/>
  </joint>
  <link name="base_camera">
    <visual>
      <origin rpy="0 1.57075 0.4"/>
      <geometry>
        <cylinder length="0.04" radius="0.025"/>
      </geometry>
      <material name="gray"/>
    </visual>
    <collision>
      <origin rpy="0 1.57075 0.4"/>
      <geometry>
        <cylinder length="0.04" radius="0.025"/>
      </geometry>
    </collision>
  </link>
  <joint name="to_base_camera" type="fixed">
    <parent link="head"/>
    <child link="base_camera"/>
    <origin xyz="0.16000000000000003 0.1 0.046000000000000006"/>
  </joint>
  <link name="camera">
    <visual>
      <origin rpy="0 1.57075 0.4"/>
      <geometry>
        <cylinder length="0.035" radius="0.015"/>
      </geometry>
      <material name="gray"/>
    </visual>
    <collision>
      <origin rpy="0 1.57075 0.4"/>
      <geometry>
        <cylinder length="0.035" radius="0.015"/>
      </geometry>
    </collision>
  </link>
  <joint name="to_camera" type="fixed">
    <parent link="base_camera"/>
    <child link="camera"/>
    <origin xyz="0.03 0.010000000000000002 0.0"/>
  </joint>
  <link name="red_light">
    <visual>
      <origin rpy="0 1.57075 0.22999999999999998"/>
      <geometry>
        <cylinder length="0.03" radius="0.018000000000000002"/>
      </geometry>
      <material name="red"/>
    </visual>
    <collision>
      <origin rpy="0 1.57075 0.22999999999999998"/>
      <geometry>
        <cylinder length="0.03" radius="0.018000000000000002"/>
      </geometry>
    </collision>
  </link>
  <joint name="to_red_light" type="fixed">
    <parent link="base_light"/>
    <child link="red_light"/>
    <origin xyz="0.03 0.0 0.001"/>
  </joint>
  <link name="antena">
    <visual>
      <origin rpy="-0.30000000000000004 0.2 0.30000000000000004"/>
      <geometry>
        <cylinder length="0.04" radius="0.017"/>
      </geometry>
      <material name="gray"/>
    </visual>
    <collision>
      <origin rpy="0 0.2 0.30000000000000004"/>
      <geometry>
        <cylinder length="0.04" radius="0.017"/>
      </geometry>
    </collision>
  </link>
  <joint name="to_antena" type="fixed">
    <parent link="head"/>
    <child link="antena"/>
    <origin xyz="0.06 0.1 0.17"/>
  </joint>
  <link name="pupil">
    <visual>
      <geometry>
        <sphere radius="0.03"/>
      </geometry>
      <material name="black"/>
    </visual>
    <collision>
      <geometry>
        <sphere radius="0.03"/>
      </geometry>
    </collision>
  </link>
  <joint name="pupil_eye" type="fixed">
    <parent link="eye"/>
    <child link="pupil"/>
    <origin xyz="0.03 0.0 0.001"/>
  </joint>
  <!-- _______________________ OTHER DEFINITIONS ________________________-->
  <joint name="gripper_extension" type="prismatic">
    <parent link="base_link"/>
    <child link="gripper_pole"/>
    <limit effort="1000.0" lower="-0.38" upper="0" velocity="0.5"/>
    <origin rpy="0 0 0" xyz="0.19 0.1 0.05"/>
  </joint>
  <link name="gripper_pole">
    <visual>
      <geometry>
        <cylinder length="0.2" radius="0.01"/>
      </geometry>
      <origin rpy="0 1.5707963267948966 0 " xyz="0.1 0 0"/>
    </visual>
    <collision>
      <geometry>
        <cylinder length="0.2" radius="0.01"/>
      </geometry>
      <origin rpy="0 1.5707963267948966 0 " xyz="0.1 0 0"/>
    </collision>
    <inertial>
      <mass value="0.05"/>
      <inertia ixx="1.0" ixy="0.0" ixz="0.0" iyy="1.0" iyz="0.0" izz="1.0"/>
    </inertial>
  </link>
</robot>
